Workbook
Name UPDATE: 'Data Sheet'!$E$1

Sheet Financials>>>

Sheet Historical Financial
B2: ="HISTORICAL FINANCIAL STATEMENT" & "-" & 'Data Sheet'!B1 -> HISTORICAL FINANCIAL STATEMENT-TATA CONSUMER PRODUCTS LTD
B3: YEAR | C3: ='Data Sheet'!B16 -> 42460 | D3: ='Data Sheet'!C16 -> 42825 | E3: ='Data Sheet'!D16 -> 43190 | F3: ='Data Sheet'!E16 -> 43555 | G3: ='Data Sheet'!F16 -> 43921 | H3: ='Data Sheet'!G16 -> 44286 | I3: ='Data Sheet'!H16 -> 44651 | J3: ='Data Sheet'!I16 -> 45016 | ... L3: ='Data Sheet'!K16 -> 45747 | M3: LTM
A5: # | B5: Income Statement
B6: ='Data Sheet'!A17 -> Sales | C6: =IFERROR('Data Sheet'!B17,0) -> 6636.54 | D6: =IFERROR('Data Sheet'!C17,0) -> 6779.55 | E6: =IFERROR('Data Sheet'!D17,0) -> 6815.35 | F6: =IFERROR('Data Sheet'!E17,0) -> 7251.5 | G6: =IFERROR('Data Sheet'!F17,0) -> 9637.42 | H6: =IFERROR('Data Sheet'!G17,0) -> 11602.03 | I6: =IFERROR('Data Sheet'!H17,0) -> 12425.37 | J6: =IFERROR('Data Sheet'!I17,0) -> 13783.16 | ... L6: =IFERROR('Data Sheet'!K17,0) -> 17618.3 | M6: =IFERROR(SUM('Data Sheet'!H42:K42),0) -> 19465.03
B7: Sales Growth% | C7: - | D7: =IFERROR(D6/C6-1,0) -> 0.021548879 | E7: =IFERROR(E6/D6-1,0) -> 0.0052805865 | F7: =IFERROR(F6/E6-1,0) -> 0.063995246 | G7: =IFERROR(G6/F6-1,0) -> 0.32902434 | H7: =IFERROR(H6/G6-1,0) -> 0.20385228 | I7: =IFERROR(I6/H6-1,0) -> 0.070965167 | J7: =IFERROR(J6/I6-1,0) -> 0.10927562 | K7: =IFERROR(K6/J6-1,0) -> 0.10321944 | ... M7: =IFERROR(M6/L6-1,0) -> 0.10481885
B9: Cost of Good Sold | C9: =IFERROR(SUM('Data Sheet'!B18,'Data Sheet'!B20:B22)-1*'Data Sheet'!C19,0) -> 4677.44 | D9: =IFERROR(SUM('Data Sheet'!C18,'Data Sheet'!C20:C22)-1*'Data Sheet'!C19,0) -> 4680.71 | E9: =IFERROR(SUM('Data Sheet'!D18,'Data Sheet'!D20:D22)-1*'Data Sheet'!D19,0) -> 4802.44 | F9: =IFERROR(SUM('Data Sheet'!E18,'Data Sheet'!E20:E22)-1*'Data Sheet'!E19,0) -> 5112.81 | G9: =IFERROR(SUM('Data Sheet'!F18,'Data Sheet'!F20:F22)-1*'Data Sheet'!F19,0) -> 6637.79 | H9: =IFERROR(SUM('Data Sheet'!G18,'Data Sheet'!G20:G22)-1*'Data Sheet'!G19,0) -> 8227.59 | I9: =IFERROR(SUM('Data Sheet'!H18,'Data Sheet'!H20:H22)-1*'Data Sheet'!H19,0) -> 8594.93 | J9: =IFERROR(SUM('Data Sheet'!I18,'Data Sheet'!I20:I22)-1*'Data Sheet'!I19,0) -> 9681.17 | K9: =IFERROR(SUM('Data Sheet'!J18,'Data Sheet'!J20:J22)-1*'Data Sheet'!J19,0) -> 10354.23 | L9: =IFERROR(SUM('Data Sheet'!K18,'Data Sheet'!K20:K22)-1*'Data Sheet'!K19,0) -> 12092.75 | M9: =IFERROR(SUM('Data Sheet'!H43:K43),0) -> 16844.69
B10: COGS % Sales | C10: =IFERROR(C9/C6,0) -> 0.704801 | D10: =IFERROR(D9/D6,0) -> 0.69041603 | E10: =IFERROR(E9/E6,0) -> 0.70465053 | F10: =IFERROR(F9/F6,0) -> 0.7050693 | G10: =IFERROR(G9/G6,0) -> 0.68875176 | H10: =IFERROR(H9/H6,0) -> 0.7091509 | I10: =IFERROR(I9/I6,0) -> 0.69172427 | J10: =IFERROR(J9/J6,0) -> 0.70239118 | ... M10: =IFERROR(M9/M6,0) -> 0.86538218
B12: Gross Profit | C12: =C6-C9 -> 1959.1 | D12: =D6-D9 -> 2098.84 | E12: =E6-E9 -> 2012.91 | F12: =F6-F9 -> 2138.69 | G12: =G6-G9 -> 2999.63 | H12: =H6-H9 -> 3374.44 | I12: =I6-I9 -> 3830.44 | J12: =J6-J9 -> 4101.99 | ... M12: =M6-M9 -> 2620.34
B13: Gross Margin | C13: =C12/C6 -> 0.295199 | D13: =D12/D6 -> 0.30958397 | E13: =E12/E6 -> 0.29534947 | F13: =F12/F6 -> 0.2949307 | G13: =G12/G6 -> 0.31124824 | H13: =H12/H6 -> 0.2908491 | I13: =I12/I6 -> 0.30827573 | J13: =J12/J6 -> 0.29760882 | ... M13: =M12/M6 -> 0.13461782
B15: ='Data Sheet'!A23 -> Selling and admin | C15: =IFERROR(SUM('Data Sheet'!B24),0) -> 649.51 | D15: =IFERROR(SUM('Data Sheet'!C24),0) -> 380.79 | E15: =IFERROR(SUM('Data Sheet'!D24),0) -> 316.36 | F15: =IFERROR(SUM('Data Sheet'!E24),0) -> 384.55 | G15: =IFERROR(SUM('Data Sheet'!F24),0) -> 429.32 | H15: =IFERROR(SUM('Data Sheet'!G24),0) -> 409.22 | I15: =IFERROR(SUM('Data Sheet'!H24),0) -> 419.83 | J15: =IFERROR(SUM('Data Sheet'!I24),0) -> 460.26 | ... M15: =IFERROR(SUM('Data Sheet'!L24),0) -> 0
B16: S$G Exp % Sales | C16: =IFERROR(C15/C6,0) -> 0.097868769 | D16: =IFERROR(D15/D6,0) -> 0.056167445 | E16: =IFERROR(E15/E6,0) -> 0.046418746 | F16: =IFERROR(F15/F6,0) -> 0.053030408 | G16: =IFERROR(G15/G6,0) -> 0.044547192 | H16: =IFERROR(H15/H6,0) -> 0.035271414 | I16: =IFERROR(I15/I6,0) -> 0.033788129 | J16: =IFERROR(J15/J6,0) -> 0.033392923 | ... M16: =IFERROR(M15/M6,0) -> 0
B18: EBITDA | C18: =C12-C15 -> 1309.59 | D18: =D12-D15 -> 1718.05 | E18: =E12-E15 -> 1696.55 | F18: =F12-F15 -> 1754.14 | G18: =G12-G15 -> 2570.31 | H18: =H12-H15 -> 2965.22 | I18: =I12-I15 -> 3410.61 | J18: =J12-J15 -> 3641.73 | ... L18: =L12-L15 -> 4732.72 | M18: =IFERROR(SUM('Data Sheet'!H45:K45,'Data Sheet'!H46:K46,'Data Sheet'!H48:K48),0) -> 1258.15
B19: EBITDA % Sales | C19: =IFERROR(C18/C6,0) -> 0.19733024 | D19: =IFERROR(D18/D6,0) -> 0.25341652 | E19: =IFERROR(E18/E6,0) -> 0.24893072 | F19: =IFERROR(F18/F6,0) -> 0.2419003 | G19: =IFERROR(G18/G6,0) -> 0.26670105 | H19: =IFERROR(H18/H6,0) -> 0.25557769 | I19: =IFERROR(I18/I6,0) -> 0.2744876 | J19: =IFERROR(J18/J6,0) -> 0.2642159 | ... M19: =IFERROR(M18/M6,0) -> 0.064636427
B21: ='Data Sheet'!A26 -> Depreciation | C21: =IFERROR('Data Sheet'!B26,0) -> 116.79 | D21: =IFERROR('Data Sheet'!C26,0) -> 126.04 | E21: =IFERROR('Data Sheet'!D26,0) -> 116.04 | F21: =IFERROR('Data Sheet'!E26,0) -> 122.57 | G21: =IFERROR('Data Sheet'!F26,0) -> 241.71 | H21: =IFERROR('Data Sheet'!G26,0) -> 254.74 | I21: =IFERROR('Data Sheet'!H26,0) -> 278.01 | J21: =IFERROR('Data Sheet'!I26,0) -> 304.08 | ... L21: =IFERROR('Data Sheet'!K26,0) -> 600.74 | M21: =IFERROR(SUM('Data Sheet'!H45:K45),0) -> 614.59
B22: Depreciation % Sales | C22: =C21/C6 -> 0.017598025 | D22: =D21/D6 -> 0.018591204 | E22: =E21/E6 -> 0.017026272 | F22: =F21/F6 -> 0.01690271 | G22: =G21/G6 -> 0.025080364 | H22: =H21/H6 -> 0.021956502 | I22: =I21/I6 -> 0.022374384 | J22: =J21/J6 -> 0.022061704 | ... M22: =M21/M6 -> 0.031574059
B24: ='Data Sheet'!A27 -> Interest | C24: =IFERROR('Data Sheet'!B27,0) -> 116.9 | D24: =IFERROR('Data Sheet'!C27,0) -> 91.53 | E24: =IFERROR('Data Sheet'!D27,0) -> 42.76 | F24: =IFERROR('Data Sheet'!E27,0) -> 52.47 | G24: =IFERROR('Data Sheet'!F27,0) -> 77.86 | H24: =IFERROR('Data Sheet'!G27,0) -> 68.69 | I24: =IFERROR('Data Sheet'!H27,0) -> 72.78 | J24: =IFERROR('Data Sheet'!I27,0) -> 87.16 | ... L24: =IFERROR('Data Sheet'!K27,0) -> 290.2 | M24: =IFERROR(SUM('Data Sheet'!H46:K46),0) -> 138.6
B25: Interest % Sales | C25: =C24/C6 -> 0.0176146 | D25: =D24/D6 -> 0.013500896 | E25: =E24/E6 -> 0.0062740725 | F25: =F24/F6 -> 0.0072357443 | G25: =G24/G6 -> 0.0080789257 | H25: =H24/H6 -> 0.0059205156 | I25: =I24/I6 -> 0.0058573708 | J25: =J24/J6 -> 0.0063236587 | ... M25: =M24/M6 -> 0.0071204617
B27: Earning After Tax | C27: =C18-C21-C24 -> 1075.9 | D27: =D18-D21-D24 -> 1500.48 | E27: =E18-E21-E24 -> 1537.75 | F27: =F18-F21-F24 -> 1579.1 | G27: =G18-G21-G24 -> 2250.74 | H27: =H18-H21-H24 -> 2641.79 | I27: =I18-I21-I24 -> 3059.82 | J27: =J18-J21-J24 -> 3250.49 | ... M27: =M18-M21-M24 -> 504.96
B28: EBT % Sales | C28: =C27/C6 -> 0.16211761 | D28: =D27/D6 -> 0.22132442 | E28: =E27/E6 -> 0.22563038 | F28: =F27/F6 -> 0.21776184 | G28: =G27/G6 -> 0.23354176 | H28: =H27/H6 -> 0.22770067 | I28: =I27/I6 -> 0.24625585 | J28: =J27/J6 -> 0.23583054 | ... M28: =M27/M6 -> 0.025941907
B30: Tax | C30: ='Data Sheet'!B29 -> 200.01 | D30: ='Data Sheet'!C29 -> 198.31 | E30: ='Data Sheet'!D29 -> 185.87 | F30: ='Data Sheet'!E29 -> 260.88 | G30: ='Data Sheet'!F29 -> 274.19 | H30: ='Data Sheet'!G29 -> 317.27 | I30: ='Data Sheet'!H29 -> 377.04 | J30: ='Data Sheet'!I29 -> 447.04 | ... L30: ='Data Sheet'!K29 -> 396.24 | M30: =IFERROR(SUM('Data Sheet'!H29:K29),0) -> 1615.05
B31: Tax % Sales | C31: =C30/C6 -> 0.030137692 | D31: =D30/D6 -> 0.029251204 | E31: =E30/E6 -> 0.02727226 | F31: =F30/F6 -> 0.035976005 | G31: =G30/G6 -> 0.02845056 | H31: =H30/H6 -> 0.027346077 | I31: =I30/I6 -> 0.030344368 | J31: =J30/J6 -> 0.032433782 | ... M31: =M30/M6 -> 0.082971873
B33: Net Profit | C33: =C27-C30 -> 875.89 | D33: =D27-D30 -> 1302.17 | E33: =E27-E30 -> 1351.88 | F33: =F27-F30 -> 1318.22 | G33: =G27-G30 -> 1976.55 | H33: =H27-H30 -> 2324.52 | I33: =I27-I30 -> 2682.78 | J33: =J27-J30 -> 2803.45 | ... M33: =M27-M30 -> -1110.09
B34: Net Profit % Sales | C34: =C33/C6 -> 0.13197992 | D34: =D33/D6 -> 0.19207322 | E34: =E33/E6 -> 0.19835812 | F34: =F33/F6 -> 0.18178584 | G34: =G33/G6 -> 0.2050912 | H34: =H33/H6 -> 0.20035459 | I34: =I33/I6 -> 0.21591148 | J34: =J33/J6 -> 0.20339675 | ... M34: =M33/M6 -> -0.057029966
B36: No.of Equity Share | C36: =IFERROR('Data Sheet'!B93,0) -> 65.54 | D36: =IFERROR('Data Sheet'!C93,0) -> 65.54 | E36: =IFERROR('Data Sheet'!D93,0) -> 65.54 | F36: =IFERROR('Data Sheet'!E93,0) -> 65.54 | G36: =IFERROR('Data Sheet'!F93,0) -> 95.7 | H36: =IFERROR('Data Sheet'!G93,0) -> 95.7 | I36: =IFERROR('Data Sheet'!H93,0) -> 95.7 | J36: =IFERROR('Data Sheet'!I93,0) -> 96.47 | ... L36: =IFERROR('Data Sheet'!K93,0) -> 98.95 | M36: =L36 -> 98.95
B38: EPS | C38: =IFERROR(C33/C36,0) -> 13.364205 | D38: =IFERROR(D33/D36,0) -> 19.868325 | E38: =IFERROR(E33/E36,0) -> 20.626793 | F38: =IFERROR(F33/F36,0) -> 20.113213 | G38: =IFERROR(G33/G36,0) -> 20.653605 | H38: =IFERROR(H33/H36,0) -> 24.289655 | I38: =IFERROR(I33/I36,0) -> 28.033229 | J38: =IFERROR(J33/J36,0) -> 29.06033 | ... M38: =IFERROR(M33/M36,0) -> -11.218696
B39: EPS Growth | C39: - | D39: =IFERROR(D38/C38-1,0) -> 0.48668212 | E39: =IFERROR(E38/D38-1,0) -> 0.038174739 | F39: =IFERROR(F38/E38-1,0) -> -0.02489866 | G39: =IFERROR(G38/F38-1,0) -> 0.026867498 | H39: =IFERROR(H38/G38-1,0) -> 0.17604918 | I39: =IFERROR(I38/H38-1,0) -> 0.15412214 | J39: =IFERROR(J38/I38-1,0) -> 0.036638691 | K39: =IFERROR(K38/J38-1,0) -> 0.15094329 | ... M39: =IFERROR(M38/L38-1,0) -> -1.3221817
B41: Dividend Per Share | C41: =IFERROR('Data Sheet'!B31/'Historical Financial'!C38,0) -> 10.625398 | D41: =IFERROR('Data Sheet'!C31/'Historical Financial'!D38,0) -> 7.4646455 | E41: =IFERROR('Data Sheet'!D31/'Historical Financial'!E38,0) -> 7.1901629 | F41: =IFERROR('Data Sheet'!E31/'Historical Financial'!F38,0) -> 7.8445944 | G41: =IFERROR('Data Sheet'!F31/'Historical Financial'!G38,0) -> 12.047776 | H41: =IFERROR('Data Sheet'!G31/'Historical Financial'!H38,0) -> 15.366624 | I41: =IFERROR('Data Sheet'!H31/'Historical Financial'!I38,0) -> 19.88961 | J41: =IFERROR('Data Sheet'!I31/'Historical Financial'!J38,0) -> 27.01277 | ... L41: =IFERROR('Data Sheet'!K31/'Historical Financial'!L38,0) -> 23.443885 | M41: -
B42: Dividend Pay out Ratio | C42: =C41/C38 -> 0.79506399 | D42: =D41/D38 -> 0.37570583 | E42: =E41/E38 -> 0.34858366 | F42: =F41/F38 -> 0.39002194 | G42: =G41/G38 -> 0.58332556 | H42: =H41/H38 -> 0.63264068 | I42: =I41/I38 -> 0.70950123 | J42: =J41/J38 -> 0.92954107 | ... L42: =L41/L38 -> 0.67326817 | M42: -
B44: Retain Earning | C44: =IFERROR(IF(C38>C41,C38-C41,0),0) -> 2.7388069 | D44: =IFERROR(IF(D38>D41,D38-D41,0),0) -> 12.403679 | E44: =IFERROR(IF(E38>E41,E38-E41,0),0) -> 13.43663 | F44: =IFERROR(IF(F38>F41,F38-F41,0),0) -> 12.268619 | G44: =IFERROR(IF(G38>G41,G38-G41,0),0) -> 8.6058293 | H44: =IFERROR(IF(H38>H41,H38-H41,0),0) -> 8.9230311 | I44: =IFERROR(IF(I38>I41,I38-I41,0),0) -> 8.1436184 | J44: =IFERROR(IF(J38>J41,J38-J41,0),0) -> 2.0475597 | ... M44: =IFERROR(IF(M38>M41,M38-M41,0),0) -> 0
A47: # | B47: Balance sheet
B49: ='Data Sheet'!A57 -> Equity Share Capital | C49: =IFERROR('Data Sheet'!B57,0) -> 63.11 | D49: =IFERROR('Data Sheet'!C57,0) -> 63.11 | E49: =IFERROR('Data Sheet'!D57,0) -> 63.11 | F49: =IFERROR('Data Sheet'!E57,0) -> 63.11 | G49: =IFERROR('Data Sheet'!F57,0) -> 92.16 | H49: =IFERROR('Data Sheet'!G57,0) -> 92.16 | I49: =IFERROR('Data Sheet'!H57,0) -> 92.16 | J49: =IFERROR('Data Sheet'!I57,0) -> 92.9 | ... L49: =IFERROR('Data Sheet'!K57,0) -> 98.95
B50: ='Data Sheet'!A58 -> Reserves | C50: =IFERROR('Data Sheet'!B58,0) -> 6184.06 | D50: =IFERROR('Data Sheet'!C58,0) -> 6202.39 | E50: =IFERROR('Data Sheet'!D58,0) -> 6968.49 | F50: =IFERROR('Data Sheet'!E58,0) -> 7268.58 | G50: =IFERROR('Data Sheet'!F58,0) -> 13722.7 | H50: =IFERROR('Data Sheet'!G58,0) -> 14442.35 | I50: =IFERROR('Data Sheet'!H58,0) -> 15049.78 | J50: =IFERROR('Data Sheet'!I58,0) -> 16183.81 | ... L50: =IFERROR('Data Sheet'!K58,0) -> 19902.13
B51: ='Data Sheet'!A59 -> Borrowings | C51: =IFERROR('Data Sheet'!B59,0) -> 1354.05 | D51: =IFERROR('Data Sheet'!C59,0) -> 786.56 | E51: =IFERROR('Data Sheet'!D59,0) -> 1067.58 | F51: =IFERROR('Data Sheet'!E59,0) -> 1141.1 | G51: =IFERROR('Data Sheet'!F59,0) -> 1586.32 | H51: =IFERROR('Data Sheet'!G59,0) -> 1633.55 | I51: =IFERROR('Data Sheet'!H59,0) -> 1412.01 | J51: =IFERROR('Data Sheet'!I59,0) -> 1600.04 | ... L51: =IFERROR('Data Sheet'!K59,0) -> 2392.68
B52: ='Data Sheet'!A60 -> Other Liabilities | C52: =IFERROR('Data Sheet'!B60,0) -> 2293.54 | D52: =IFERROR('Data Sheet'!C60,0) -> 2499.35 | E52: =IFERROR('Data Sheet'!D60,0) -> 2361.58 | F52: =IFERROR('Data Sheet'!E60,0) -> 2407.89 | G52: =IFERROR('Data Sheet'!F60,0) -> 3071.86 | H52: =IFERROR('Data Sheet'!G60,0) -> 4049.76 | I52: =IFERROR('Data Sheet'!H60,0) -> 4520.92 | J52: =IFERROR('Data Sheet'!I60,0) -> 4885.74 | ... L52: =IFERROR('Data Sheet'!K60,0) -> 9436.86
B53: Total Liabilities | C53: =IFERROR('Data Sheet'!B61,0) -> 9894.76 | D53: =IFERROR('Data Sheet'!C61,0) -> 9551.41 | E53: =IFERROR('Data Sheet'!D61,0) -> 10460.76 | F53: =IFERROR('Data Sheet'!E61,0) -> 10880.68 | G53: =IFERROR('Data Sheet'!F61,0) -> 18473.04 | H53: =IFERROR('Data Sheet'!G61,0) -> 20217.82 | I53: =IFERROR('Data Sheet'!H61,0) -> 21074.87 | J53: =IFERROR('Data Sheet'!I61,0) -> 22762.49 | ... L53: =IFERROR('Data Sheet'!K61,0) -> 31830.62
B55: ='Data Sheet'!A62 -> Net Block | C55: ='Data Sheet'!B62 -> 4661.8 | D55: ='Data Sheet'!C62 -> 4572.59 | E55: ='Data Sheet'!D62 -> 4798.18 | F55: ='Data Sheet'!E62 -> 4913.31 | G55: ='Data Sheet'!F62 -> 11656.04 | H55: ='Data Sheet'!G62 -> 12023.13 | I55: ='Data Sheet'!H62 -> 12599.35 | ... L55: ='Data Sheet'!K62 -> 21476.84
B56: ='Data Sheet'!A63 -> Capital Work in Progress | C56: =IFERROR('Data Sheet'!B63,0) -> 39.42 | D56: =IFERROR('Data Sheet'!C63,0) -> 63.19 | E56: =IFERROR('Data Sheet'!D63,0) -> 135.16 | F56: =IFERROR('Data Sheet'!E63,0) -> 424.41 | G56: =IFERROR('Data Sheet'!F63,0) -> 95.35 | H56: =IFERROR('Data Sheet'!G63,0) -> 112.85 | I56: =IFERROR('Data Sheet'!H63,0) -> 246.97 | J56: =IFERROR('Data Sheet'!I63,0) -> 294.9 | ... L56: =IFERROR('Data Sheet'!K63,0) -> 218.1
B57: ='Data Sheet'!A64 -> Investments | C57: =IFERROR('Data Sheet'!B64,0) -> 1365.94 | D57: =IFERROR('Data Sheet'!C64,0) -> 1451.04 | E57: =IFERROR('Data Sheet'!D64,0) -> 1161.33 | F57: =IFERROR('Data Sheet'!E64,0) -> 1187.66 | G57: =IFERROR('Data Sheet'!F64,0) -> 1322.85 | H57: =IFERROR('Data Sheet'!G64,0) -> 805.89 | I57: =IFERROR('Data Sheet'!H64,0) -> 797.28 | J57: =IFERROR('Data Sheet'!I64,0) -> 1432.97 | ... L57: =IFERROR('Data Sheet'!K64,0) -> 968.67
B58: ='Data Sheet'!A65 -> Other Assets | C58: =IFERROR('Data Sheet'!B65- SUM('Data Sheet'!B67:B69),0) -> 1105.13 | D58: =IFERROR('Data Sheet'!C65- SUM('Data Sheet'!C67:C69),0) -> 844.36 | E58: =IFERROR('Data Sheet'!D65- SUM('Data Sheet'!D67:D69),0) -> 1031.36 | F58: =IFERROR('Data Sheet'!E65- SUM('Data Sheet'!E67:E69),0) -> 1032.6 | G58: =IFERROR('Data Sheet'!F65- SUM('Data Sheet'!F67:F69),0) -> 1142.9 | H58: =IFERROR('Data Sheet'!G65- SUM('Data Sheet'!G67:G69),0) -> 1190.59 | I58: =IFERROR('Data Sheet'!H65- SUM('Data Sheet'!H67:H69),0) -> 1729.72 | J58: =IFERROR('Data Sheet'!I65- SUM('Data Sheet'!I67:I69),0) -> 1667.64 | ... L58: =IFERROR('Data Sheet'!K65- SUM('Data Sheet'!K67:K69),0) -> 1879.45
B59: Total Non- current Assets | C59: =IFERROR(SUM(C55:C58),0) -> 7172.29 | D59: =IFERROR(SUM(D55:D58),0) -> 6931.18 | E59: =IFERROR(SUM(E55:E58),0) -> 7126.03 | F59: =IFERROR(SUM(F55:F58),0) -> 7557.98 | G59: =IFERROR(SUM(G55:G58),0) -> 14217.14 | H59: =IFERROR(SUM(H55:H58),0) -> 14132.46 | I59: =IFERROR(SUM(I55:I58),0) -> 15373.32 | J59: =IFERROR(SUM(J55:J58),0) -> 16465.55 | ... L59: =IFERROR(SUM(L55:L58),0) -> 24543.06
...

Sheet Ratio Analysis
B2: ="Ratio Analysis" & "-" & 'Data Sheet'!B1 -> Ratio Analysis-TATA CONSUMER PRODUCTS LTD
B3: Particular | C3: ='Data Sheet'!B16 -> 42460 | D3: ='Data Sheet'!C16 -> 42825 | E3: ='Data Sheet'!D16 -> 43190 | F3: ='Data Sheet'!E16 -> 43555 | G3: ='Data Sheet'!F16 -> 43921 | H3: ='Data Sheet'!G16 -> 44286 | I3: ='Data Sheet'!H16 -> 44651 | J3: ='Data Sheet'!I16 -> 45016 | ... L3: ='Data Sheet'!K16 -> 45747 | M3: Trend | N3: Mean | O3: Median
B5: Sales Growth | C5: - | D5: =IFERROR('Historical Financial'!D7,0) -> 0.021548879 | E5: =IFERROR('Historical Financial'!E7,0) -> 0.0052805865 | F5: =IFERROR('Historical Financial'!F7,0) -> 0.063995246 | G5: =IFERROR('Historical Financial'!G7,0) -> 0.32902434 | H5: =IFERROR('Historical Financial'!H7,0) -> 0.20385228 | I5: =IFERROR('Historical Financial'!I7,0) -> 0.070965167 | J5: =IFERROR('Historical Financial'!J7,0) -> 0.10927562 | K5: =IFERROR('Historical Financial'!K7,0) -> 0.10321944 | L5: =IFERROR('Historical Financial'!L7,0) -> 0.15865276 | N5: =AVERAGE(C5:L5) -> 0.11842381 | O5: =MEDIAN(C5:L5) -> 0.10321944
B6: EBITDA Growth | C6: - | D6: =IFERROR('Historical Financial'!D19/'Historical Financial'!C19-1,0) -> 0.28422552 | E6: =IFERROR('Historical Financial'!E19/'Historical Financial'!D19-1,0) -> -0.017701301 | F6: =IFERROR('Historical Financial'!F19/'Historical Financial'!E19-1,0) -> -0.028242501 | G6: =IFERROR('Historical Financial'!G19/'Historical Financial'!F19-1,0) -> 0.10252468 | H6: =IFERROR('Historical Financial'!H19/'Historical Financial'!G19-1,0) -> -0.041707219 | I6: =IFERROR('Historical Financial'!I19/'Historical Financial'!H19-1,0) -> 0.073988904 | J6: =IFERROR('Historical Financial'!J19/'Historical Financial'!I19-1,0) -> -0.037421372 | K6: =IFERROR('Historical Financial'!K19/'Historical Financial'!J19-1,0) -> 0.048193291 | L6: =IFERROR('Historical Financial'!L19/'Historical Financial'!K19-1,0) -> -0.030056385 | N6: =AVERAGE(C6:L6) -> 0.039311513 | O6: =MEDIAN(C6:L6) -> -0.017701301
B7: EBIT Growth | C7: - | D7: =IFERROR('Historical Financial'!D28/'Historical Financial'!C28-1,0) -> 0.36520903 | E7: =IFERROR('Historical Financial'!E28/'Historical Financial'!D28-1,0) -> 0.019455396 | F7: =IFERROR('Historical Financial'!F28/'Historical Financial'!E28-1,0) -> -0.034873567 | G7: =IFERROR('Historical Financial'!G28/'Historical Financial'!F28-1,0) -> 0.072464094 | H7: =IFERROR('Historical Financial'!H28/'Historical Financial'!G28-1,0) -> -0.025010891 | I7: =IFERROR('Historical Financial'!I28/'Historical Financial'!H28-1,0) -> 0.081489336 | J7: =IFERROR('Historical Financial'!J28/'Historical Financial'!I28-1,0) -> -0.042335282 | K7: =IFERROR('Historical Financial'!K28/'Historical Financial'!J28-1,0) -> 0.032985536 | L7: =IFERROR('Historical Financial'!L28/'Historical Financial'!K28-1,0) -> -0.10489453 | N7: =AVERAGE(C7:L7) -> 0.040498792 | O7: =MEDIAN(C7:L7) -> 0.019455396
B8: Net Profit Growth | C8: - | D8: =IFERROR('Historical Financial'!D33/'Historical Financial'!C33-1,0) -> 0.48668212 | E8: =IFERROR('Historical Financial'!E33/'Historical Financial'!D33-1,0) -> 0.038174739 | F8: =IFERROR('Historical Financial'!F33/'Historical Financial'!E33-1,0) -> -0.02489866 | G8: =IFERROR('Historical Financial'!G33/'Historical Financial'!F33-1,0) -> 0.49940829 | H8: =IFERROR('Historical Financial'!H33/'Historical Financial'!G33-1,0) -> 0.17604918 | I8: =IFERROR('Historical Financial'!I33/'Historical Financial'!H33-1,0) -> 0.15412214 | J8: =IFERROR('Historical Financial'!J33/'Historical Financial'!I33-1,0) -> 0.044979462 | K8: =IFERROR('Historical Financial'!K33/'Historical Financial'!J33-1,0) -> 0.18053113 | L8: =IFERROR('Historical Financial'!L33/'Historical Financial'!K33-1,0) -> 0.041087033 | N8: =AVERAGE(C8:L8) -> 0.17734838 | O8: =MEDIAN(C8:L8) -> 0.15412214
B9: Dividend Growth | C9: - | D9: =IFERROR('Historical Financial'!D41/'Historical Financial'!C41-1,0) -> -0.29747146 | E9: =IFERROR('Historical Financial'!E41/'Historical Financial'!D41-1,0) -> -0.036771015 | F9: =IFERROR('Historical Financial'!F41/'Historical Financial'!E41-1,0) -> 0.091017617 | G9: =IFERROR('Historical Financial'!G41/'Historical Financial'!F41-1,0) -> 0.53580607 | H9: =IFERROR('Historical Financial'!H41/'Historical Financial'!G41-1,0) -> 0.27547395 | I9: =IFERROR('Historical Financial'!I41/'Historical Financial'!H41-1,0) -> 0.29433832 | J9: =IFERROR('Historical Financial'!J41/'Historical Financial'!I41-1,0) -> 0.3581347 | K9: =IFERROR('Historical Financial'!K41/'Historical Financial'!J41-1,0) -> -0.18270307 | L9: =IFERROR('Historical Financial'!L41/'Historical Financial'!K41-1,0) -> 0.061892587 | N9: =AVERAGE(C9:L9) -> 0.12219086 | O9: =MEDIAN(C9:L9) -> 0.091017617
B11: Gross Margin | C11: =IFERROR('Historical Financial'!C13,0) -> 0.295199 | D11: =IFERROR('Historical Financial'!D13,0) -> 0.30958397 | E11: =IFERROR('Historical Financial'!E13,0) -> 0.29534947 | F11: =IFERROR('Historical Financial'!F13,0) -> 0.2949307 | G11: =IFERROR('Historical Financial'!G13,0) -> 0.31124824 | H11: =IFERROR('Historical Financial'!H13,0) -> 0.2908491 | I11: =IFERROR('Historical Financial'!I13,0) -> 0.30827573 | J11: =IFERROR('Historical Financial'!J13,0) -> 0.29760882 | ... L11: =IFERROR('Historical Financial'!L13,0) -> 0.31362561 | N11: =AVERAGE(C11:L11) -> 0.30357334 | O11: =MEDIAN(C11:L11) -> 0.30294228
B12: EBITDA Margin | C12: =IFERROR('Historical Financial'!C19,0) -> 0.19733024 | D12: =IFERROR('Historical Financial'!D19,0) -> 0.25341652 | E12: =IFERROR('Historical Financial'!E19,0) -> 0.24893072 | F12: =IFERROR('Historical Financial'!F19,0) -> 0.2419003 | G12: =IFERROR('Historical Financial'!G19,0) -> 0.26670105 | H12: =IFERROR('Historical Financial'!H19,0) -> 0.25557769 | I12: =IFERROR('Historical Financial'!I19,0) -> 0.2744876 | J12: =IFERROR('Historical Financial'!J19,0) -> 0.2642159 | ... L12: =IFERROR('Historical Financial'!L19,0) -> 0.26862524 | N12: =AVERAGE(C12:L12) -> 0.25481346 | O12: =MEDIAN(C12:L12) -> 0.25989679
B13: EBIT Margin | C13: =IFERROR(('Historical Financial'!C18-'Historical Financial'!C21)/'Historical Financial'!C6,0) -> 0.17973221 | D13: =IFERROR(('Historical Financial'!D18-'Historical Financial'!D21)/'Historical Financial'!D6,0) -> 0.23482532 | E13: =IFERROR(('Historical Financial'!E18-'Historical Financial'!E21)/'Historical Financial'!E6,0) -> 0.23190445 | F13: =IFERROR(('Historical Financial'!F18-'Historical Financial'!F21)/'Historical Financial'!F6,0) -> 0.22499759 | G13: =IFERROR(('Historical Financial'!G18-'Historical Financial'!G21)/'Historical Financial'!G6,0) -> 0.24162068 | H13: =IFERROR(('Historical Financial'!H18-'Historical Financial'!H21)/'Historical Financial'!H6,0) -> 0.23362119 | I13: =IFERROR(('Historical Financial'!I18-'Historical Financial'!I21)/'Historical Financial'!I6,0) -> 0.25211322 | J13: =IFERROR(('Historical Financial'!J18-'Historical Financial'!J21)/'Historical Financial'!J6,0) -> 0.24215419 | ... L13: =IFERROR(('Historical Financial'!L18-'Historical Financial'!L21)/'Historical Financial'!L6,0) -> 0.23452774 | N13: =AVERAGE(C13:L13) -> 0.2327643 | O13: =MEDIAN(C13:L13) -> 0.23467653
B14: Ebt Margin | C14: =IFERROR('Historical Financial'!C28,0) -> 0.16211761 | D14: =IFERROR('Historical Financial'!D28,0) -> 0.22132442 | E14: =IFERROR('Historical Financial'!E28,0) -> 0.22563038 | F14: =IFERROR('Historical Financial'!F28,0) -> 0.21776184 | G14: =IFERROR('Historical Financial'!G28,0) -> 0.23354176 | H14: =IFERROR('Historical Financial'!H28,0) -> 0.22770067 | I14: =IFERROR('Historical Financial'!I28,0) -> 0.24625585 | J14: =IFERROR('Historical Financial'!J28,0) -> 0.23583054 | ... L14: =IFERROR('Historical Financial'!L28,0) -> 0.21805623 | N14: =AVERAGE(C14:L14) -> 0.22318288 | O14: =MEDIAN(C14:L14) -> 0.22666552
B15: Net Profit Margin | C15: =IFERROR('Historical Financial'!C34,0) -> 0.13197992 | D15: =IFERROR('Historical Financial'!D34,0) -> 0.19207322 | E15: =IFERROR('Historical Financial'!E34,0) -> 0.19835812 | F15: =IFERROR('Historical Financial'!F34,0) -> 0.18178584 | G15: =IFERROR('Historical Financial'!G34,0) -> 0.2050912 | H15: =IFERROR('Historical Financial'!H34,0) -> 0.20035459 | I15: =IFERROR('Historical Financial'!I34,0) -> 0.21591148 | J15: =IFERROR('Historical Financial'!J34,0) -> 0.20339675 | ... L15: =IFERROR('Historical Financial'!L34,0) -> 0.19556597 | N15: =AVERAGE(C15:L15) -> 0.19421675 | O15: =MEDIAN(C15:L15) -> 0.19935636
B17: Sales Expenses% sales | C17: =IFERROR('Historical Financial'!C10,0) -> 0.704801 | D17: =IFERROR('Historical Financial'!D10,0) -> 0.69041603 | E17: =IFERROR('Historical Financial'!E10,0) -> 0.70465053 | F17: =IFERROR('Historical Financial'!F10,0) -> 0.7050693 | G17: =IFERROR('Historical Financial'!G10,0) -> 0.68875176 | H17: =IFERROR('Historical Financial'!H10,0) -> 0.7091509 | I17: =IFERROR('Historical Financial'!I10,0) -> 0.69172427 | J17: =IFERROR('Historical Financial'!J10,0) -> 0.70239118 | ... L17: =IFERROR('Historical Financial'!L10,0) -> 0.68637439 | N17: =AVERAGE(C17:L17) -> 0.69642666 | O17: =MEDIAN(C17:L17) -> 0.69705772
B18: Depreciation % Sales | C18: =IFERROR('Historical Financial'!C22,0) -> 0.017598025 | D18: =IFERROR('Historical Financial'!D22,0) -> 0.018591204 | E18: =IFERROR('Historical Financial'!E22,0) -> 0.017026272 | F18: =IFERROR('Historical Financial'!F22,0) -> 0.01690271 | G18: =IFERROR('Historical Financial'!G22,0) -> 0.025080364 | H18: =IFERROR('Historical Financial'!H22,0) -> 0.021956502 | I18: =IFERROR('Historical Financial'!I22,0) -> 0.022374384 | J18: =IFERROR('Historical Financial'!J22,0) -> 0.022061704 | ... L18: =IFERROR('Historical Financial'!L22,0) -> 0.034097501 | N18: =AVERAGE(C18:L18) -> 0.022049162 | O18: =MEDIAN(C18:L18) -> 0.022009103
B19: OperatingIncome%Sales | C19: =C13 -> 0.17973221 | D19: =D13 -> 0.23482532 | E19: =E13 -> 0.23190445 | F19: =F13 -> 0.22499759 | G19: =G13 -> 0.24162068 | H19: =H13 -> 0.23362119 | I19: =I13 -> 0.25211322 | J19: =J13 -> 0.24215419 | ... L19: =L13 -> 0.23452774 | N19: =AVERAGE(C19:L19) -> 0.2327643 | O19: =MEDIAN(C19:L19) -> 0.23467653
B21: Return On Capital Employed | C21: =IFERROR(('Historical Financial'!C18-'Historical Financial'!C21)/SUM('Historical Financial'!C49:C51),0) -> 0.15692218 | D21: =IFERROR(('Historical Financial'!D18-'Historical Financial'!D21)/SUM('Historical Financial'!D49:D51),0) -> 0.22575106 | E21: =IFERROR(('Historical Financial'!E18-'Historical Financial'!E21)/SUM('Historical Financial'!E49:E51),0) -> 0.19514445 | F21: =IFERROR(('Historical Financial'!F18-'Historical Financial'!F21)/SUM('Historical Financial'!F49:F51),0) -> 0.19256585 | G21: =IFERROR(('Historical Financial'!G18-'Historical Financial'!G21)/SUM('Historical Financial'!G49:G51),0) -> 0.15119621 | H21: =IFERROR(('Historical Financial'!H18-'Historical Financial'!H21)/SUM('Historical Financial'!H49:H51),0) -> 0.16764411 | I21: =IFERROR(('Historical Financial'!I18-'Historical Financial'!I21)/SUM('Historical Financial'!I49:I51),0) -> 0.1892358 | J21: =IFERROR(('Historical Financial'!J18-'Historical Financial'!J21)/SUM('Historical Financial'!J49:J51),0) -> 0.1867034 | ... L21: =IFERROR(('Historical Financial'!L18-'Historical Financial'!L21)/SUM('Historical Financial'!L49:L51),0) -> 0.18451479 | N21: =AVERAGE(C21:L21) -> 0.1845956 | O21: =MEDIAN(C21:L21) -> 0.1879696
B22: Reatained Earnings% | C22: =IFERROR('Historical Financial'!C44/'Historical Financial'!C38,0) -> 0.20493601 | D22: =IFERROR('Historical Financial'!D44/'Historical Financial'!D38,0) -> 0.62429417 | E22: =IFERROR('Historical Financial'!E44/'Historical Financial'!E38,0) -> 0.65141634 | F22: =IFERROR('Historical Financial'!F44/'Historical Financial'!F38,0) -> 0.60997806 | G22: =IFERROR('Historical Financial'!G44/'Historical Financial'!G38,0) -> 0.41667444 | H22: =IFERROR('Historical Financial'!H44/'Historical Financial'!H38,0) -> 0.36735932 | I22: =IFERROR('Historical Financial'!I44/'Historical Financial'!I38,0) -> 0.29049877 | J22: =IFERROR('Historical Financial'!J44/'Historical Financial'!J38,0) -> 0.070458927 | ... L22: =IFERROR('Historical Financial'!L44/'Historical Financial'!L38,0) -> 0.32673183 | N22: =AVERAGE(C22:L22) -> 0.3902271 | O22: =MEDIAN(C22:L22) -> 0.35364121
B23: Return on Equity% | C23: =IFERROR('Historical Financial'!C33/SUM('Historical Financial'!C49:C50),0) -> 0.14020589 | D23: =IFERROR('Historical Financial'!D33/SUM('Historical Financial'!D49:D50),0) -> 0.20783178 | E23: =IFERROR('Historical Financial'!E33/SUM('Historical Financial'!E49:E50),0) -> 0.19225781 | F23: =IFERROR('Historical Financial'!F33/SUM('Historical Financial'!F49:F50),0) -> 0.17979756 | G23: =IFERROR('Historical Financial'!G33/SUM('Historical Financial'!G49:G50),0) -> 0.1430742 | H23: =IFERROR('Historical Financial'!H33/SUM('Historical Financial'!H49:H50),0) -> 0.15993109 | I23: =IFERROR('Historical Financial'!I33/SUM('Historical Financial'!I49:I50),0) -> 0.17717545 | J23: =IFERROR('Historical Financial'!J33/SUM('Historical Financial'!J49:J50),0) -> 0.1722369 | ... L23: =IFERROR('Historical Financial'!L33/SUM('Historical Financial'!L49:L50),0) -> 0.1722677 | N23: =AVERAGE(C23:L23) -> 0.17508943 | O23: =MEDIAN(C23:L23) -> 0.17472157
B24: Self Sustained Growth Rate | C24: =IFERROR(C22*C23,0) -> 0.028733235 | D24: =IFERROR(D22*D23,0) -> 0.12974817 | E24: =IFERROR(E22*E23,0) -> 0.12523988 | F24: =IFERROR(F22*F23,0) -> 0.10967257 | G24: =IFERROR(G22*G23,0) -> 0.059615361 | H24: =IFERROR(H22*H23,0) -> 0.058752175 | I24: =IFERROR(I22*I23,0) -> 0.051469249 | J24: =IFERROR(J22*J23,0) -> 0.012135627 | ... L24: =IFERROR(L22*L23,0) -> 0.05628534 | N24: =AVERAGE(C24:L24) -> 0.070171516 | O24: =MEDIAN(C24:L24) -> 0.059183768
B25: Interest Coverage Ratio | C25: =IFERROR(('Historical Financial'!C18-'Historical Financial'!C21)/'Historical Financial'!C24,0) -> 10.203593 | D25: =IFERROR(('Historical Financial'!D18-'Historical Financial'!D21)/'Historical Financial'!D24,0) -> 17.393314 | E25: =IFERROR(('Historical Financial'!E18-'Historical Financial'!E21)/'Historical Financial'!E24,0) -> 36.962348 | F25: =IFERROR(('Historical Financial'!F18-'Historical Financial'!F21)/'Historical Financial'!F24,0) -> 31.095293 | G25: =IFERROR(('Historical Financial'!G18-'Historical Financial'!G21)/'Historical Financial'!G24,0) -> 29.907526 | H25: =IFERROR(('Historical Financial'!H18-'Historical Financial'!H21)/'Historical Financial'!H24,0) -> 39.459601 | I25: =IFERROR(('Historical Financial'!I18-'Historical Financial'!I21)/'Historical Financial'!I24,0) -> 43.042045 | J25: =IFERROR(('Historical Financial'!J18-'Historical Financial'!J21)/'Historical Financial'!J24,0) -> 38.293369 | ... L25: =IFERROR(('Historical Financial'!L18-'Historical Financial'!L21)/'Historical Financial'!L24,0) -> 14.238387 | N25: =AVERAGE(C25:L25) -> 29.013172 | O25: =MEDIAN(C25:L25) -> 30.501409
B27: Debtor Turnover Ratio | C27: =IFERROR('Historical Financial'!C6/'Historical Financial'!C61,0) -> 11.202235 | D27: =IFERROR('Historical Financial'!D6/'Historical Financial'!D61,0) -> 11.443244 | E27: =IFERROR('Historical Financial'!E6/'Historical Financial'!E61,0) -> 10.512973 | F27: =IFERROR('Historical Financial'!F6/'Historical Financial'!F61,0) -> 10.655352 | G27: =IFERROR('Historical Financial'!G6/'Historical Financial'!G61,0) -> 10.448087 | H27: =IFERROR('Historical Financial'!H6/'Historical Financial'!H61,0) -> 15.239361 | I27: =IFERROR('Historical Financial'!I6/'Historical Financial'!I61,0) -> 14.87801 | J27: =IFERROR('Historical Financial'!J6/'Historical Financial'!J61,0) -> 17.264991 | ... L27: =IFERROR('Historical Financial'!L6/'Historical Financial'!L61,0) -> 20.255809 | N27: =AVERAGE(C27:L27) -> 13.885668 | O27: =MEDIAN(C27:L27) -> 13.160627
B28: Creditor Turnover Ratio | C28: =IFERROR('Historical Financial'!C6/'Historical Financial'!C52,0) -> 2.8935794 | D28: =IFERROR('Historical Financial'!D6/'Historical Financial'!D52,0) -> 2.7125253 | E28: =IFERROR('Historical Financial'!E6/'Historical Financial'!E52,0) -> 2.8859281 | F28: =IFERROR('Historical Financial'!F6/'Historical Financial'!F52,0) -> 3.0115578 | G28: =IFERROR('Historical Financial'!G6/'Historical Financial'!G52,0) -> 3.137324 | H28: =IFERROR('Historical Financial'!H6/'Historical Financial'!H52,0) -> 2.8648685 | I28: =IFERROR('Historical Financial'!I6/'Historical Financial'!I52,0) -> 2.7484163 | J28: =IFERROR('Historical Financial'!J6/'Historical Financial'!J52,0) -> 2.8210998 | ... L28: =IFERROR('Historical Financial'!L6/'Historical Financial'!L52,0) -> 1.8669663 | N28: =AVERAGE(C28:L28) -> 2.6764464 | O28: =MEDIAN(C28:L28) -> 2.8429842
B29: Inventory Turnover Ratio | C29: =IFERROR('Historical Financial'!C6/'Historical Financial'!C62,0) -> 4.0739713 | D29: =IFERROR('Historical Financial'!D6/'Historical Financial'!D62,0) -> 4.6660266 | E29: =IFERROR('Historical Financial'!E6/'Historical Financial'!E62,0) -> 4.705726 | F29: =IFERROR('Historical Financial'!F6/'Historical Financial'!F62,0) -> 4.5081254 | G29: =IFERROR('Historical Financial'!G6/'Historical Financial'!G62,0) -> 5.6292355 | H29: =IFERROR('Historical Financial'!H6/'Historical Financial'!H62,0) -> 5.1583836 | I29: =IFERROR('Historical Financial'!I6/'Historical Financial'!I62,0) -> 5.4821598 | J29: =IFERROR('Historical Financial'!J6/'Historical Financial'!J62,0) -> 5.1017186 | ... L29: =IFERROR('Historical Financial'!L6/'Historical Financial'!L62,0) -> 4.8940946 | N29: =AVERAGE(C29:L29) -> 4.9710206 | O29: =MEDIAN(C29:L29) -> 4.9979066
B30: Fixed Assest Turnover | C30: =IFERROR('Historical Financial'!C6/'Historical Financial'!C55,0) -> 1.4236003 | D30: =IFERROR('Historical Financial'!D6/'Historical Financial'!D55,0) -> 1.4826499 | E30: =IFERROR('Historical Financial'!E6/'Historical Financial'!E55,0) -> 1.4204032 | F30: =IFERROR('Historical Financial'!F6/'Historical Financial'!F55,0) -> 1.475889 | G30: =IFERROR('Historical Financial'!G6/'Historical Financial'!G55,0) -> 0.82681768 | H30: =IFERROR('Historical Financial'!H6/'Historical Financial'!H55,0) -> 0.96497584 | I30: =IFERROR('Historical Financial'!I6/'Historical Financial'!I55,0) -> 0.98619135 | J30: =IFERROR('Historical Financial'!J6/'Historical Financial'!J55,0) -> 1.0545614 | ... L30: =IFERROR('Historical Financial'!L6/'Historical Financial'!L55,0) -> 0.82033949 | N30: =AVERAGE(C30:L30) -> 1.1240939 | O30: =MEDIAN(C30:L30) -> 1.0203764
B31: Capital Turnover Ratio | C31: =IFERROR('Historical Financial'!C6/SUM('Historical Financial'!C49:C50),0) -> 1.0623274 | D31: =IFERROR('Historical Financial'!D6/SUM('Historical Financial'!D49:D50),0) -> 1.0820445 | E31: =IFERROR('Historical Financial'!E6/SUM('Historical Financial'!E49:E50),0) -> 0.96924598 | F31: =IFERROR('Historical Financial'!F6/SUM('Historical Financial'!F49:F50),0) -> 0.98906255 | G31: =IFERROR('Historical Financial'!G6/SUM('Historical Financial'!G49:G50),0) -> 0.69761257 | H31: =IFERROR('Historical Financial'!H6/SUM('Historical Financial'!H49:H50),0) -> 0.79824019 | I31: =IFERROR('Historical Financial'!I6/SUM('Historical Financial'!I49:I50),0) -> 0.820593 | J31: =IFERROR('Historical Financial'!J6/SUM('Historical Financial'!J49:J50),0) -> 0.84680258 | ... L31: =IFERROR('Historical Financial'!L6/SUM('Historical Financial'!L49:L50),0) -> 0.88086743 | N31: =AVERAGE(C31:L31) -> 0.90938006 | O31: =MEDIAN(C31:L31) -> 0.91393589
B33: Debtors Days | C33: =IFERROR(365/C27,0) -> 32.582784 | D33: =IFERROR(365/D27,0) -> 31.896549 | E33: =IFERROR(365/E27,0) -> 34.719009 | F33: =IFERROR(365/F27,0) -> 34.255085 | G33: =IFERROR(365/G27,0) -> 34.934625 | H33: =IFERROR(365/H27,0) -> 23.951136 | I33: =IFERROR(365/I27,0) -> 24.532851 | J33: =IFERROR(365/J27,0) -> 21.141048 | ... L33: =IFERROR(365/L27,0) -> 18.019522 | N33: =AVERAGE(C33:L33) -> 27.755812 | O33: =MEDIAN(C33:L33) -> 28.2147
B34: Payable Days | C34: =IFERROR(365/C28,0) -> 126.14135 | D34: =IFERROR(365/D28,0) -> 134.56096 | E34: =IFERROR(365/E28,0) -> 126.47578 | F34: =IFERROR(365/F28,0) -> 121.19973 | G34: =IFERROR(365/G28,0) -> 116.34119 | H34: =IFERROR(365/H28,0) -> 127.4055 | I34: =IFERROR(365/I28,0) -> 132.80376 | J34: =IFERROR(365/J28,0) -> 129.38217 | ... L34: =IFERROR(365/L28,0) -> 195.50433 | N34: =AVERAGE(C34:L34) -> 141.01222 | O34: =MEDIAN(C34:L34) -> 128.39383
B35: Investory Days | C35: =IFERROR(365/C29,0) -> 89.593169 | D35: =IFERROR(365/D29,0) -> 78.225015 | E35: =IFERROR(365/E29,0) -> 77.565077 | F35: =IFERROR(365/F29,0) -> 80.964918 | G35: =IFERROR(365/G29,0) -> 64.840066 | H35: =IFERROR(365/H29,0) -> 70.7586 | I35: =IFERROR(365/I29,0) -> 66.579599 | J35: =IFERROR(365/J29,0) -> 71.544519 | ... L35: =IFERROR(365/L29,0) -> 74.579679 | N35: =AVERAGE(C35:L35) -> 74.11259 | O35: =MEDIAN(C35:L35) -> 73.062099
B36: Cash Conversion Cycle | C36: =IFERROR(SUM(C33,C35)-C34,0) -> -3.9653946 | D36: =IFERROR(SUM(D33,D35)-D34,0) -> -24.439395 | E36: =IFERROR(SUM(E33,E35)-E34,0) -> -14.191692 | F36: =IFERROR(SUM(F33,F35)-F34,0) -> -5.9797283 | G36: =IFERROR(SUM(G33,G35)-G34,0) -> -16.566498 | H36: =IFERROR(SUM(H33,H35)-H34,0) -> -32.695761 | I36: =IFERROR(SUM(I33,I35)-I34,0) -> -41.691306 | J36: =IFERROR(SUM(J33,J35)-J34,0) -> -36.696599 | ... L36: =IFERROR(SUM(L33,L35)-L34,0) -> -102.90513 | N36: =AVERAGE(C36:L36) -> -39.143816 | O36: =MEDIAN(C36:L36) -> -28.567578
B38: CFO/Sales | C38: =IFERROR('Historical Financial'!C102/'Historical Financial'!C6,0) -> 0.017478988 | D38: =IFERROR('Historical Financial'!D102/'Historical Financial'!D6,0) -> 0.10915179 | E38: =IFERROR('Historical Financial'!E102/'Historical Financial'!E6,0) -> 0.052235028 | F38: =IFERROR('Historical Financial'!F102/'Historical Financial'!F6,0) -> 0.028959526 | G38: =IFERROR('Historical Financial'!G102/'Historical Financial'!G6,0) -> 0.11237447 | H38: =IFERROR('Historical Financial'!H102/'Historical Financial'!H6,0) -> 0.14273364 | I38: =IFERROR('Historical Financial'!I102/'Historical Financial'!I6,0) -> 0.12200844 | J38: =IFERROR('Historical Financial'!J102/'Historical Financial'!J6,0) -> 0.10599891 | ... L38: =IFERROR('Historical Financial'!L102/'Historical Financial'!L6,0) -> 0.1167536 | N38: =AVERAGE(C38:L38) -> 0.093501382 | O38: =MEDIAN(C38:L38) -> 0.11076313
B39: CFO/Total Assets | C39: =IFERROR('Historical Financial'!C102/'Historical Financial'!C66,0) -> 0.011723377 | D39: =IFERROR('Historical Financial'!D102/'Historical Financial'!D66,0) -> 0.077475472 | E39: =IFERROR('Historical Financial'!E102/'Historical Financial'!E66,0) -> 0.034031944 | F39: =IFERROR('Historical Financial'!F102/'Historical Financial'!F66,0) -> 0.019300264 | G39: =IFERROR('Historical Financial'!G102/'Historical Financial'!G66,0) -> 0.058625976 | H39: =IFERROR('Historical Financial'!H102/'Historical Financial'!H66,0) -> 0.081907941 | I39: =IFERROR('Historical Financial'!I102/'Historical Financial'!I66,0) -> 0.071934014 | J39: =IFERROR('Historical Financial'!J102/'Historical Financial'!J66,0) -> 0.064184542 | ... L39: =IFERROR('Historical Financial'!L102/'Historical Financial'!L66,0) -> 0.064623309 | N39: =AVERAGE(C39:L39) -> 0.055325031 | O39: =MEDIAN(C39:L39) -> 0.064403926
B40: CFO/Total Debt | C40: =IFERROR('Historical Financial'!C102/'Historical Financial'!C51,0) -> 0.085668919 | D40: =IFERROR('Historical Financial'!D102/'Historical Financial'!D51,0) -> 0.94080553 | E40: =IFERROR('Historical Financial'!E102/'Historical Financial'!E51,0) -> 0.33346447 | F40: =IFERROR('Historical Financial'!F102/'Historical Financial'!F51,0) -> 0.18403295 | G40: =IFERROR('Historical Financial'!G102/'Historical Financial'!G51,0) -> 0.68271219 | H40: =IFERROR('Historical Financial'!H102/'Historical Financial'!H51,0) -> 1.0137431 | I40: =IFERROR('Historical Financial'!I102/'Historical Financial'!I51,0) -> 1.0736468 | J40: =IFERROR('Historical Financial'!J102/'Historical Financial'!J51,0) -> 0.91310217 | ... L40: =IFERROR('Historical Financial'!L102/'Historical Financial'!L51,0) -> 0.85970543 | N40: =AVERAGE(C40:L40) -> 0.66436481 | O40: =MEDIAN(C40:L40) -> 0.77120881

Sheet Forcasting 
B2: Sales Forcasting - Tata Consumer Products | G2: EBITDA Forcasting - Tata Consumer Products | L2: EPS Forcasting - Tata Consumer Products
B3: Year Weight | C3: Year | D3: Sales | E3: Sales Growth | G3: Year Weight | H3: Year | I3: EBITBA | J3: EBITDA Growth | L3: Year Weight | M3: Year | N3: EPS | O3: EPS Growth
B4: 1 | C4: ='Historical Financial'!$C$3 -> 42460 | D4: ='Historical Financial'!$C$6 -> 6636.54 | E4: - | G4: 1 | H4: ='Historical Financial'!$C$3 -> 42460 | I4: ='Historical Financial'!C18 -> 1309.59 | J4: - | L4: 1 | M4: ='Historical Financial'!$C$3 -> 42460 | N4: ='Historical Financial'!C38 -> 13.364205 | O4: -
B5: =B4+1 -> 2 | C5: =365+C4 -> 42825 | D5: ='Historical Financial'!$D$6 -> 6779.55 | E5: =D5/D4 -> 1.0215489 | G5: =G4+1 -> 2 | H5: =365+H4 -> 42825 | I5: ='Historical Financial'!D18 -> 1718.05 | J5: =I5/I4 -> 1.3118991 | L5: =L4+1 -> 2 | M5: =365+M4 -> 42825 | N5: ='Historical Financial'!D38 -> 19.868325 | O5: =N5/N4 -> 1.4866821
B6: =B5+1 -> 3 | C6: =365+C5 -> 43190 | D6: ='Historical Financial'!$E$6 -> 6815.35 | E6: =D6/D5 -> 1.0052806 | G6: =G5+1 -> 3 | H6: =365+H5 -> 43190 | I6: ='Historical Financial'!E18 -> 1696.55 | J6: =I6/I5 -> 0.98748581 | L6: =L5+1 -> 3 | M6: =365+M5 -> 43190 | N6: ='Historical Financial'!E38 -> 20.626793 | O6: =N6/N5 -> 1.0381747
B7: =B6+1 -> 4 | C7: =365+C6 -> 43555 | D7: ='Historical Financial'!$F$6 -> 7251.5 | E7: =D7/D6 -> 1.0639952 | G7: =G6+1 -> 4 | H7: =365+H6 -> 43555 | I7: ='Historical Financial'!F18 -> 1754.14 | J7: =I7/I6 -> 1.0339454 | L7: =L6+1 -> 4 | M7: =365+M6 -> 43555 | N7: ='Historical Financial'!F38 -> 20.113213 | O7: =N7/N6 -> 0.97510134
B8: =B7+1 -> 5 | C8: =365+C7 -> 43920 | D8: ='Historical Financial'!$G$6 -> 9637.42 | E8: =D8/D7 -> 1.3290243 | G8: =G7+1 -> 5 | H8: =365+H7 -> 43920 | I8: ='Historical Financial'!G18 -> 2570.31 | J8: =I8/I7 -> 1.4652821 | L8: =L7+1 -> 5 | M8: =365+M7 -> 43920 | N8: ='Historical Financial'!G38 -> 20.653605 | O8: =N8/N7 -> 1.0268675
B9: =B8+1 -> 6 | C9: =365+C8 -> 44285 | D9: ='Historical Financial'!$H$6 -> 11602.03 | E9: =D9/D8 -> 1.2038523 | G9: =G8+1 -> 6 | H9: =365+H8 -> 44285 | I9: ='Historical Financial'!H18 -> 2965.22 | J9: =I9/I8 -> 1.1536429 | L9: =L8+1 -> 6 | M9: =365+M8 -> 44285 | N9: ='Historical Financial'!H38 -> 24.289655 | O9: =N9/N8 -> 1.1760492
B10: =B9+1 -> 7 | C10: =365+C9 -> 44650 | D10: ='Historical Financial'!$I$6 -> 12425.37 | E10: =D10/D9 -> 1.0709652 | G10: =G9+1 -> 7 | H10: =365+H9 -> 44650 | I10: ='Historical Financial'!I18 -> 3410.61 | J10: =I10/I9 -> 1.1502047 | L10: =L9+1 -> 7 | M10: =365+M9 -> 44650 | N10: ='Historical Financial'!I38 -> 28.033229 | O10: =N10/N9 -> 1.1541221
B11: =B10+1 -> 8 | C11: =365+C10 -> 45015 | D11: ='Historical Financial'!$J$6 -> 13783.16 | E11: =D11/D10 -> 1.1092756 | G11: =G10+1 -> 8 | H11: =365+H10 -> 45015 | I11: ='Historical Financial'!J18 -> 3641.73 | J11: =I11/I10 -> 1.067765 | L11: =L10+1 -> 8 | M11: =365+M10 -> 45015 | N11: ='Historical Financial'!J38 -> 29.06033 | O11: =N11/N10 -> 1.0366387
B12: =B11+1 -> 9 | C12: =365+C11 -> 45380 | D12: ='Historical Financial'!$K$6 -> 15205.85 | E12: =D12/D11 -> 1.1032194 | G12: =G11+1 -> 9 | H12: =365+H11 -> 45380 | I12: ='Historical Financial'!K18 -> 4211.25 | J12: =I12/I11 -> 1.1563872 | L12: =L11+1 -> 9 | M12: =365+M11 -> 45380 | N12: ='Historical Financial'!K38 -> 33.446791 | O12: =N12/N11 -> 1.1509433
B13: =B12+1 -> 10 | C13: =365+C12 -> 45745 | D13: ='Historical Financial'!$L$6 -> 17618.3 | E13: =D13/D12 -> 1.1586528 | G13: =G12+1 -> 10 | H13: =365+H12 -> 45745 | I13: ='Historical Financial'!L18 -> 4732.72 | J13: =I13/I12 -> 1.1238278 | L13: =L12+1 -> 10 | M13: =365+M12 -> 45745 | N13: ='Historical Financial'!L38 -> 34.821021 | O13: =N13/N12 -> 1.041087
B14: =B13+1 -> 11 | C14: =365+C13 -> 46110 | D14: =FORECAST(B14,$D$4:$D$13,$B$4:$B$13) -> 17780.347 | E14: =D14/D13 -> 1.0091977 | G14: =G13+1 -> 11 | H14: =365+H13 -> 46110 | I14: =FORECAST(G14,$I$4:$I$13,$G$4:$G$13) -> 4912.71 | J14: =I14/I13 -> 1.038031 | L14: =L13+1 -> 11 | M14: =365+M13 -> 46110 | N14: =FORECAST(L14,$N$4:$N$13,$L$4:$L$13) -> 36.351863 | O14: =N14/N13 -> 1.0439632
B15: =B14+1 -> 12 | C15: =365+C14 -> 46475 | D15: =FORECAST(B15,$D$4:$D$13,$B$4:$B$13) -> 19053.955 | E15: =D15/D14 -> 1.0716301 | G15: =G14+1 -> 12 | H15: =365+H14 -> 46475 | I15: =FORECAST(G15,$I$4:$I$13,$G$4:$G$13) -> 5296.6542 | J15: =I15/I14 -> 1.0781532 | L15: =L14+1 -> 12 | M15: =365+M14 -> 46475 | N15: =FORECAST(L15,$N$4:$N$13,$L$4:$L$13) -> 38.51989 | O15: =N15/N14 -> 1.05964
B16: =B15+1 -> 13 | C16: =365+C15 -> 46840 | D16: =FORECAST(B16,$D$4:$D$13,$B$4:$B$13) -> 20327.562 | E16: =D16/D15 -> 1.0668422 | G16: =G15+1 -> 13 | H16: =365+H15 -> 46840 | I16: =FORECAST(G16,$I$4:$I$13,$G$4:$G$13) -> 5680.5984 | J16: =I16/I15 -> 1.0724881 | L16: =L15+1 -> 13 | M16: =365+M15 -> 46840 | N16: =FORECAST(L16,$N$4:$N$13,$L$4:$L$13) -> 40.687916 | O16: =N16/N15 -> 1.0562833
B17: =B16+1 -> 14 | C17: =365+C16 -> 47205 | D17: =FORECAST(B17,$D$4:$D$13,$B$4:$B$13) -> 21601.169 | E17: =D17/D16 -> 1.0626542 | G17: =G16+1 -> 14 | H17: =365+H16 -> 47205 | I17: =FORECAST(G17,$I$4:$I$13,$G$4:$G$13) -> 6064.5425 | J17: =I17/I16 -> 1.0675887 | L17: =L16+1 -> 14 | M17: =365+M16 -> 47205 | N17: =FORECAST(L17,$N$4:$N$13,$L$4:$L$13) -> 42.855943 | O17: =N17/N16 -> 1.0532843
B18: =B17+1 -> 15 | C18: =365+C17 -> 47570 | D18: =FORECAST(B18,$D$4:$D$13,$B$4:$B$13) -> 22874.777 | E18: =D18/D17 -> 1.0589601 | G18: =G17+1 -> 15 | H18: =365+H17 -> 47570 | I18: =FORECAST(G18,$I$4:$I$13,$G$4:$G$13) -> 6448.4867 | J18: =I18/I17 -> 1.0633097 | L18: =L17+1 -> 15 | M18: =365+M17 -> 47570 | N18: =FORECAST(L18,$N$4:$N$13,$L$4:$L$13) -> 45.023969 | O18: =N18/N17 -> 1.0505887

Sheet Comman Size 
B2: ="Comman Size Income Statement" & "-" & 'Data Sheet'!B1 -> Comman Size Income Statement-TATA CONSUMER PRODUCTS LTD
B4: Particulars | D4: ='Historical Financial'!C$3 -> 42460 | E4: ='Historical Financial'!D$3 -> 42825 | F4: ='Historical Financial'!E$3 -> 43190 | G4: ='Historical Financial'!F$3 -> 43555 | H4: ='Historical Financial'!G$3 -> 43921 | I4: ='Historical Financial'!H$3 -> 44286 | J4: ='Historical Financial'!I$3 -> 44651 | K4: ='Historical Financial'!J$3 -> 45016 | ... M4: ='Historical Financial'!L$3 -> 45747
B6: ='Data Sheet'!A17 -> Sales | D6: ='Data Sheet'!B17/'Data Sheet'!B17 -> 1 | E6: ='Data Sheet'!C17/'Data Sheet'!C17 -> 1 | F6: ='Data Sheet'!D17/'Data Sheet'!D17 -> 1 | G6: ='Data Sheet'!E17/'Data Sheet'!E17 -> 1 | H6: ='Data Sheet'!F17/'Data Sheet'!F17 -> 1 | I6: ='Data Sheet'!G17/'Data Sheet'!G17 -> 1 | J6: ='Data Sheet'!H17/'Data Sheet'!H17 -> 1 | K6: ='Data Sheet'!I17/'Data Sheet'!I17 -> 1 | ... M6: ='Data Sheet'!K17/'Data Sheet'!K17 -> 1
B7: ='Data Sheet'!A18 -> Raw Material Cost | D7: ='Data Sheet'!B18/'Data Sheet'!B17 -> 0.54267585 | E7: ='Data Sheet'!C18/'Data Sheet'!C17 -> 0.46694102 | F7: ='Data Sheet'!D18/'Data Sheet'!D17 -> 0.54965776 | G7: ='Data Sheet'!E18/'Data Sheet'!E17 -> 0.55465076 | H7: ='Data Sheet'!F18/'Data Sheet'!F17 -> 0.56061685 | I7: ='Data Sheet'!G18/'Data Sheet'!G17 -> 0.54885136 | J7: ='Data Sheet'!H18/'Data Sheet'!H17 -> 0.50889591 | K7: ='Data Sheet'!I18/'Data Sheet'!I17 -> 0.51563357 | ... M7: ='Data Sheet'!K18/'Data Sheet'!K17 -> 0.51007645
B8: ='Data Sheet'!A19 -> Change in Inventory | D8: ='Data Sheet'!B19/'Data Sheet'!B17 -> -0.0030301934 | E8: ='Data Sheet'!C19/'Data Sheet'!C17 -> 0.00010177667 | F8: ='Data Sheet'!D19/'Data Sheet'!D17 -> 0.006866852 | G8: ='Data Sheet'!E19/'Data Sheet'!E17 -> 0.0019871751 | H8: ='Data Sheet'!F19/'Data Sheet'!F17 -> -0.00080727 | I8: ='Data Sheet'!G19/'Data Sheet'!G17 -> 0.012889124 | J8: ='Data Sheet'!H19/'Data Sheet'!H17 -> 0.0032015143 | K8: ='Data Sheet'!I19/'Data Sheet'!I17 -> 0.019870625 | ... M8: ='Data Sheet'!K19/'Data Sheet'!K17 -> 0.02057463
B9: ='Data Sheet'!A20 -> Power and Fuel | D9: ='Data Sheet'!B20/'Data Sheet'!B17 -> 0.012244332 | E9: ='Data Sheet'!C20/'Data Sheet'!C17 -> 0.012270726 | F9: ='Data Sheet'!D20/'Data Sheet'!D17 -> 0.012775573 | G9: ='Data Sheet'!E20/'Data Sheet'!E17 -> 0.012311935 | H9: ='Data Sheet'!F20/'Data Sheet'!F17 -> 0.010774668 | I9: ='Data Sheet'!G20/'Data Sheet'!G17 -> 0.0083916349 | J9: ='Data Sheet'!H20/'Data Sheet'!H17 -> 0.009971534 | K9: ='Data Sheet'!I20/'Data Sheet'!I17 -> 0.010841491 | ... M9: ='Data Sheet'!K20/'Data Sheet'!K17 -> 0.0088663492
B10: ='Data Sheet'!A21 -> Other Mfr. Exp | D10: ='Data Sheet'!B21/'Data Sheet'!B17 -> 0.028677594 | E10: ='Data Sheet'!C21/'Data Sheet'!C17 -> 0.088148918 | F10: ='Data Sheet'!D21/'Data Sheet'!D17 -> 0.028566398 | G10: ='Data Sheet'!E21/'Data Sheet'!E17 -> 0.028902986 | H10: ='Data Sheet'!F21/'Data Sheet'!F17 -> 0.024744174 | I10: ='Data Sheet'!G21/'Data Sheet'!G17 -> 0.08117114 | J10: ='Data Sheet'!H21/'Data Sheet'!H17 -> 0.091714774 | K10: ='Data Sheet'!I21/'Data Sheet'!I17 -> 0.11450204 | ... M10: ='Data Sheet'!K21/'Data Sheet'!K17 -> 0.10683494
B11: ='Data Sheet'!A22 -> Employee Cost | D11: ='Data Sheet'!B22/'Data Sheet'!$B$17 -> 0.12130719 | E11: ='Data Sheet'!C22/'Data Sheet'!C17 -> 0.12315714 | F11: ='Data Sheet'!D22/'Data Sheet'!D17 -> 0.12051765 | G11: ='Data Sheet'!E22/'Data Sheet'!E17 -> 0.11119079 | H11: ='Data Sheet'!F22/'Data Sheet'!F17 -> 0.091808804 | I11: ='Data Sheet'!G22/'Data Sheet'!G17 -> 0.083625883 | J11: ='Data Sheet'!H22/'Data Sheet'!H17 -> 0.084343565 | K11: ='Data Sheet'!I22/'Data Sheet'!I17 -> 0.081284698 | L11: ='Data Sheet'!J22/'Data Sheet'!J17 -> 0.082770118 | M11: ='Data Sheet'!K22/'Data Sheet'!K17 -> 0.081171282
B12: ='Data Sheet'!A23 -> Selling and admin | D12: ='Data Sheet'!B23/'Data Sheet'!B$17 -> 0.13906041 | E12: ='Data Sheet'!C23/'Data Sheet'!C$17 -> 0.13672294 | F12: ='Data Sheet'!D23/'Data Sheet'!D$17 -> 0.12583947 | G12: ='Data Sheet'!E23/'Data Sheet'!E$17 -> 0.13352134 | H12: ='Data Sheet'!F23/'Data Sheet'!F$17 -> 0.13262471 | I12: ='Data Sheet'!G23/'Data Sheet'!G$17 -> 0.12251821 | J12: ='Data Sheet'!H23/'Data Sheet'!H$17 -> 0.13615933 | K12: ='Data Sheet'!I23/'Data Sheet'!I$17 -> 0.12952472 | ... M12: ='Data Sheet'!K23/'Data Sheet'!K$17 -> 0.1278994
B13: ='Data Sheet'!A24 -> Other Expenses | D13: ='Data Sheet'!B24/'Data Sheet'!B$17 -> 0.097868769 | E13: ='Data Sheet'!C24/'Data Sheet'!C$17 -> 0.056167445 | F13: ='Data Sheet'!D24/'Data Sheet'!D$17 -> 0.046418746 | G13: ='Data Sheet'!E24/'Data Sheet'!E$17 -> 0.053030408 | H13: ='Data Sheet'!F24/'Data Sheet'!F$17 -> 0.044547192 | I13: ='Data Sheet'!G24/'Data Sheet'!G$17 -> 0.035271414 | J13: ='Data Sheet'!H24/'Data Sheet'!H$17 -> 0.033788129 | K13: ='Data Sheet'!I24/'Data Sheet'!I$17 -> 0.033392923 | ... M13: ='Data Sheet'!K24/'Data Sheet'!K$17 -> 0.045000369
B14: ='Data Sheet'!A25 -> Other Income | D14: ='Data Sheet'!B25/'Data Sheet'!B$17 -> 0.005656562 | E14: ='Data Sheet'!C25/'Data Sheet'!C$17 -> 0.013039214 | F14: ='Data Sheet'!D25/'Data Sheet'!D$17 -> 0.01071405 | G14: ='Data Sheet'!E25/'Data Sheet'!E$17 -> 0.017077846 | H14: ='Data Sheet'!F25/'Data Sheet'!F$17 -> -0.016933993 | I14: ='Data Sheet'!G25/'Data Sheet'!G$17 -> 0.0078201832 | J14: ='Data Sheet'!H25/'Data Sheet'!H$17 -> 0.0070822841 | K14: ='Data Sheet'!I25/'Data Sheet'!I$17 -> 0.023821098 | ... M14: ='Data Sheet'!K25/'Data Sheet'!K$17 -> 0.010678669
B15: ='Data Sheet'!A26 -> Depreciation | D15: ='Data Sheet'!B26/'Data Sheet'!B$17 -> 0.017598025 | E15: ='Data Sheet'!C26/'Data Sheet'!C$17 -> 0.018591204 | F15: ='Data Sheet'!D26/'Data Sheet'!D$17 -> 0.017026272 | G15: ='Data Sheet'!E26/'Data Sheet'!E$17 -> 0.01690271 | H15: ='Data Sheet'!F26/'Data Sheet'!F$17 -> 0.025080364 | I15: ='Data Sheet'!G26/'Data Sheet'!G$17 -> 0.021956502 | J15: ='Data Sheet'!H26/'Data Sheet'!H$17 -> 0.022374384 | K15: ='Data Sheet'!I26/'Data Sheet'!I$17 -> 0.022061704 | ... M15: ='Data Sheet'!K26/'Data Sheet'!K$17 -> 0.034097501
B16: ='Data Sheet'!A27 -> Interest | D16: ='Data Sheet'!B27/'Data Sheet'!B$17 -> 0.0176146 | E16: ='Data Sheet'!C27/'Data Sheet'!C$17 -> 0.013500896 | F16: ='Data Sheet'!D27/'Data Sheet'!D$17 -> 0.0062740725 | G16: ='Data Sheet'!E27/'Data Sheet'!E$17 -> 0.0072357443 | H16: ='Data Sheet'!F27/'Data Sheet'!F$17 -> 0.0080789257 | I16: ='Data Sheet'!G27/'Data Sheet'!G$17 -> 0.0059205156 | J16: ='Data Sheet'!H27/'Data Sheet'!H$17 -> 0.0058573708 | K16: ='Data Sheet'!I27/'Data Sheet'!I$17 -> 0.0063236587 | ... M16: ='Data Sheet'!K27/'Data Sheet'!K$17 -> 0.01647151
B17: ='Data Sheet'!A28 -> Profit before tax | D17: ='Data Sheet'!B28/'Data Sheet'!B$17 -> 0.025579594 | E17: ='Data Sheet'!C28/'Data Sheet'!C$17 -> 0.097640699 | F17: ='Data Sheet'!D28/'Data Sheet'!D$17 -> 0.11050496 | G17: ='Data Sheet'!E28/'Data Sheet'!E$17 -> 0.10131835 | H17: ='Data Sheet'!F28/'Data Sheet'!F$17 -> 0.083983058 | I17: ='Data Sheet'!G28/'Data Sheet'!G$17 -> 0.11300264 | J17: ='Data Sheet'!H28/'Data Sheet'!H$17 -> 0.1171788 | K17: ='Data Sheet'!I28/'Data Sheet'!I$17 -> 0.13012691 | ... M17: ='Data Sheet'!K28/'Data Sheet'!K$17 -> 0.10083549
B18: ='Data Sheet'!A29 -> Tax | D18: ='Data Sheet'!B29/'Data Sheet'!B$17 -> 0.030137692 | E18: ='Data Sheet'!C29/'Data Sheet'!C$17 -> 0.029251204 | F18: ='Data Sheet'!D29/'Data Sheet'!D$17 -> 0.02727226 | G18: ='Data Sheet'!E29/'Data Sheet'!E$17 -> 0.035976005 | H18: ='Data Sheet'!F29/'Data Sheet'!F$17 -> 0.02845056 | I18: ='Data Sheet'!G29/'Data Sheet'!G$17 -> 0.027346077 | J18: ='Data Sheet'!H29/'Data Sheet'!H$17 -> 0.030344368 | K18: ='Data Sheet'!I29/'Data Sheet'!I$17 -> 0.032433782 | ... M18: ='Data Sheet'!K29/'Data Sheet'!K$17 -> 0.022490252
B19: ='Data Sheet'!A30 -> Net profit | D19: ='Data Sheet'!B30/'Data Sheet'!B$17 -> -0.00083175872 | E19: ='Data Sheet'!C30/'Data Sheet'!C$17 -> 0.057443341 | F19: ='Data Sheet'!D30/'Data Sheet'!D$17 -> 0.072712333 | G19: ='Data Sheet'!E30/'Data Sheet'!E$17 -> 0.056290423 | H19: ='Data Sheet'!F30/'Data Sheet'!F$17 -> 0.047705714 | I19: ='Data Sheet'!G30/'Data Sheet'!G$17 -> 0.073839664 | J19: ='Data Sheet'!H30/'Data Sheet'!H$17 -> 0.075312043 | K19: ='Data Sheet'!I30/'Data Sheet'!I$17 -> 0.087336286 | ... M19: ='Data Sheet'!K30/'Data Sheet'!K$17 -> 0.07256489
B20: ='Data Sheet'!A31 -> Dividend Amount | D20: ='Data Sheet'!B31/'Data Sheet'!B$17 -> 0.021396692 | E20: ='Data Sheet'!C31/'Data Sheet'!C$17 -> 0.021876083 | F20: ='Data Sheet'!D31/'Data Sheet'!D$17 -> 0.021761171 | G20: ='Data Sheet'!E31/'Data Sheet'!E$17 -> 0.021758257 | H20: ='Data Sheet'!F31/'Data Sheet'!F$17 -> 0.025819151 | I20: ='Data Sheet'!G31/'Data Sheet'!G$17 -> 0.032171094 | J20: ='Data Sheet'!H31/'Data Sheet'!H$17 -> 0.044873513 | K20: ='Data Sheet'!I31/'Data Sheet'!I$17 -> 0.056953558 | ... M20: ='Data Sheet'!K31/'Data Sheet'!K$17 -> 0.046334777
B21: EBITDA | D21: ='Historical Financial'!C18/'Historical Financial'!C$6 -> 0.19733024 | E21: ='Historical Financial'!D18/'Historical Financial'!D$6 -> 0.25341652 | F21: ='Historical Financial'!E18/'Historical Financial'!E$6 -> 0.24893072 | G21: ='Historical Financial'!F18/'Historical Financial'!F$6 -> 0.2419003 | H21: ='Historical Financial'!G18/'Historical Financial'!G$6 -> 0.26670105 | I21: ='Historical Financial'!H18/'Historical Financial'!H$6 -> 0.25557769 | J21: ='Historical Financial'!I18/'Historical Financial'!I$6 -> 0.2744876 | K21: ='Historical Financial'!J18/'Historical Financial'!J$6 -> 0.2642159 | ... M21: ='Historical Financial'!L18/'Historical Financial'!L$6 -> 0.26862524
B23: ="Comman Size Balance Sheet" & "-" & 'Data Sheet'!B1 -> Comman Size Balance Sheet-TATA CONSUMER PRODUCTS LTD
B25: Particulars | D25: ='Historical Financial'!C$3 -> 42460 | E25: ='Historical Financial'!D$3 -> 42825 | F25: ='Historical Financial'!E$3 -> 43190 | G25: ='Historical Financial'!F$3 -> 43555 | H25: ='Historical Financial'!G$3 -> 43921 | I25: ='Historical Financial'!H$3 -> 44286 | J25: ='Historical Financial'!I$3 -> 44651 | K25: ='Historical Financial'!J$3 -> 45016 | ... M25: ='Historical Financial'!L$3 -> 45747
B27: Total Libilities | D27: ='Historical Financial'!C$53/'Historical Financial'!C$53 -> 1 | E27: ='Historical Financial'!D$53/'Historical Financial'!D$53 -> 1 | F27: ='Historical Financial'!E$53/'Historical Financial'!E$53 -> 1 | G27: ='Historical Financial'!F$53/'Historical Financial'!F$53 -> 1 | H27: ='Historical Financial'!G$53/'Historical Financial'!G$53 -> 1 | I27: ='Historical Financial'!H$53/'Historical Financial'!H$53 -> 1 | J27: ='Historical Financial'!I$53/'Historical Financial'!I$53 -> 1 | K27: ='Historical Financial'!J$53/'Historical Financial'!J$53 -> 1 | ... M27: ='Historical Financial'!L$53/'Historical Financial'!L$53 -> 1
B28: ='Historical Financial'!B49 -> Equity Share Capital | D28: ='Historical Financial'!C49/'Historical Financial'!C$53 -> 0.0063781234 | E28: ='Historical Financial'!D49/'Historical Financial'!D$53 -> 0.0066074014 | F28: ='Historical Financial'!E49/'Historical Financial'!E$53 -> 0.0060330225 | G28: ='Historical Financial'!F49/'Historical Financial'!F$53 -> 0.005800189 | H28: ='Historical Financial'!G49/'Historical Financial'!G$53 -> 0.0049888919 | I28: ='Historical Financial'!H49/'Historical Financial'!H$53 -> 0.004558355 | J28: ='Historical Financial'!I49/'Historical Financial'!I$53 -> 0.0043729807 | K28: ='Historical Financial'!J49/'Historical Financial'!J$53 -> 0.0040812758 | ... M28: ='Historical Financial'!L49/'Historical Financial'!L$53 -> 0.0031086419
B29: ='Historical Financial'!B50 -> Reserves | D29: ='Historical Financial'!C50/'Historical Financial'!C$53 -> 0.62498332 | E29: ='Historical Financial'!D50/'Historical Financial'!D$53 -> 0.64936905 | F29: ='Historical Financial'!E50/'Historical Financial'!E$53 -> 0.66615523 | G29: ='Historical Financial'!F50/'Historical Financial'!F$53 -> 0.66802626 | H29: ='Historical Financial'!G50/'Historical Financial'!G$53 -> 0.74285012 | I29: ='Historical Financial'!H50/'Historical Financial'!H$53 -> 0.71433765 | J29: ='Historical Financial'!I50/'Historical Financial'!I$53 -> 0.71411022 | K29: ='Historical Financial'!J50/'Historical Financial'!J$53 -> 0.71098592 | ... M29: ='Historical Financial'!L50/'Historical Financial'!L$53 -> 0.62525109
B30: ='Historical Financial'!B51 -> Borrowings | D30: ='Historical Financial'!C51/'Historical Financial'!C$53 -> 0.13684516 | E30: ='Historical Financial'!D51/'Historical Financial'!D$53 -> 0.082350145 | F30: ='Historical Financial'!E51/'Historical Financial'!E$53 -> 0.10205568 | G30: ='Historical Financial'!F51/'Historical Financial'!F$53 -> 0.10487396 | H30: ='Historical Financial'!G51/'Historical Financial'!G$53 -> 0.085872168 | I30: ='Historical Financial'!H51/'Historical Financial'!H$53 -> 0.080797534 | J30: ='Historical Financial'!I51/'Historical Financial'!I$53 -> 0.066999702 | K30: ='Historical Financial'!J51/'Historical Financial'!J$53 -> 0.070292837 | ... M30: ='Historical Financial'!L51/'Historical Financial'!L$53 -> 0.07516913
B31: ='Historical Financial'!B52 -> Other Liabilities | D31: ='Historical Financial'!C52/'Historical Financial'!C$53 -> 0.23179339 | E31: ='Historical Financial'!D52/'Historical Financial'!D$53 -> 0.26167341 | F31: ='Historical Financial'!E52/'Historical Financial'!E$53 -> 0.22575606 | G31: ='Historical Financial'!F52/'Historical Financial'!F$53 -> 0.22129959 | H31: ='Historical Financial'!G52/'Historical Financial'!G$53 -> 0.16628882 | I31: ='Historical Financial'!H52/'Historical Financial'!H$53 -> 0.20030646 | J31: ='Historical Financial'!I52/'Historical Financial'!I$53 -> 0.2145171 | K31: ='Historical Financial'!J52/'Historical Financial'!J$53 -> 0.21463996 | ... M31: ='Historical Financial'!L52/'Historical Financial'!L$53 -> 0.29647113
B33: Total Assets | D33: ='Historical Financial'!C$66/'Historical Financial'!C$66 -> 1 | E33: ='Historical Financial'!D$66/'Historical Financial'!D$66 -> 1 | F33: ='Historical Financial'!E$66/'Historical Financial'!E$66 -> 1 | G33: ='Historical Financial'!F$66/'Historical Financial'!F$66 -> 1 | H33: ='Historical Financial'!G$66/'Historical Financial'!G$66 -> 1 | I33: ='Historical Financial'!H$66/'Historical Financial'!H$66 -> 1 | J33: ='Historical Financial'!I$66/'Historical Financial'!I$66 -> 1 | K33: ='Historical Financial'!J$66/'Historical Financial'!J$66 -> 1 | ... M33: ='Historical Financial'!L$66/'Historical Financial'!L$66 -> 1
